<!--
MANSEDS Lunar Rover -- Robotic Arm: Unified Robot Description
Author: Ethan Ramsay
-->
<robot name="arm">
    <link name="chassis" />
    <link name="base_plate" />
    <link name="uprights" />
    <link name="upper_arm" />
    <link name="lower_arm" />
    <link name="hand" />
    <link name="grip" />

    <joint name="base" type="revolute">
        <parent link="chassis" />
        <child link="base_plate" />
        <orgin xyz="0 0 40" /> <!-- z from chassis level, may want reconfiguring to ground level = 0 -->
        <axis xyz="0 0 1" />
        <limit effort="1000" lower="0.0" upper="3.14" velocity="100" />
    </joint>

    <joint name="shoulder" type="revolute">
        <parent link="base_plate" />
        <child link="upper_arm" />
        <origin xyz="0 0 50" />
        <axis xyz="1 0 0" />
        <limit effort="1000" lower="0.0" upper="1.57" velocity="100" />
    </joint>

    <joint name="elbow" type="revolute">
        <parent link="upper_arm" />
        <child link="lower_arm" />
        <origin xyz="0 0 150" />
        <axis xyz="1 0 0" />
        <limit effort="1000" lower="0.0" upper="1.57" velocity="100" />
    </joint>

    <joint name="wrist" type="revolute">
        <parent link="lower_arm" />
        <child link="hand" />
        <origin xyz="0 0 260" />
        <axis xyz="1 0 0" />
        <limit effort="1000" lower="0.0" upper="1.57" velocity="100" />
    </joint>

    <joint name="knuckle" type="revolute">
        <parent link="hand" />
        <child link="grip" />
        <origin xyz="0 0 100" />
        <axis xyz="0 0 1" />
        <limit effort="1000" lower="0.0" upper="1.57" velocity="100" />
    </joint>

</robot>
